<robot name="vs060_hand">
	<gazebo>
		<plugin filename="libgazebo_ros_control.so" name="gazebo_ros_control">
			<robotNamespace>/vs060_hand</robotNamespace>
		</plugin>
	</gazebo>
	<link name="world" />
	<joint name="joint_w" type="fixed">
		<parent link="world" />
		<child link="base_link" />
	</joint>
	<link name="base_link">
		<visual>
			<origin rpy="0 0 0" xyz="0 0 0" />
			<geometry>
				<mesh filename="package://denso_robot_descriptions/vs060_description/base_link.dae" scale="1 1 1" />
			</geometry>
		</visual>
		<collision>
			<origin rpy="0 0 0" xyz="0 0 0" />
			<geometry>
				<mesh filename="package://denso_robot_descriptions/vs060_description/base_link.dae" scale="1 1 1" />
			</geometry>
		</collision>
		<inertial>
			<mass value="1000" />
			<origin rpy="0.000000 0.000000 0.000000" xyz="0.000000 0.000000 0.000000" />
			<inertia ixx="20" ixy="0" ixz="0" iyy="20" iyz="0" izz="20" />
		</inertial>
	</link>
	<link name="J1">
		<visual>
			<origin rpy="0 0 0" xyz="0 0 0" />
			<geometry>
				<mesh filename="package://denso_robot_descriptions/vs060_description/J1.dae" scale="1 1 1" />
			</geometry>
		</visual>
		<collision>
			<origin rpy="0 0 0" xyz="0 0 0" />
			<geometry>
				<mesh filename="package://denso_robot_descriptions/vs060_description/J1.dae" scale="1 1 1" />
			</geometry>
		</collision>
		<inertial>
			<mass value="4.327" />
			<origin rpy="0.000000 0.000000 0.000000" xyz="0.013885 -0.005997 0.043991" />
			<inertia ixx="0.025492" ixy="0" ixz="0" iyy="0.032502" iyz="-3.26672e-18" izz="0.01779" />
		</inertial>
	</link>
	<joint name="joint_1" type="revolute">
		<parent link="base_link" />
		<child link="J1" />
		<origin rpy="0.000000 0.000000 0.000000" xyz="0.000000 0.000000 0.181500" />
		<axis xyz="-0.000000 -0.000000 1.000000" />
 		<limit lower="-2.96706" upper="2.96706" effort="19.7336" velocity="0.5" />		<dynamics damping="10" friction="0.1" />
	</joint>
	<transmission name="trans_1">
		<type>transmission_interface/SimpleTransmission</type>
		<joint name="joint_1">
			<hardwareInterface>hardware_interface/EffortJointInterface</hardwareInterface>
		</joint>
		<actuator name="motor_1">
			<hardwareInterface>hardware_interface/EffortJointInterface</hardwareInterface>
			<mechanicalReduction>1</mechanicalReduction>
		</actuator>
	</transmission>
	<link name="J2">
		<visual>
			<origin rpy="0 0 0" xyz="0 0 0" />
			<geometry>
				<mesh filename="package://denso_robot_descriptions/vs060_description/J2.dae" scale="1 1 1" />
			</geometry>
		</visual>
		<collision>
			<origin rpy="0 0 0" xyz="0 0 0" />
			<geometry>
				<mesh filename="package://denso_robot_descriptions/vs060_description/J2.dae" scale="1 1 1" />
			</geometry>
		</collision>
		<inertial>
			<mass value="9.475" />
			<origin rpy="0.000000 0.000000 0.000000" xyz="0.015837 -0.073696 0.010087" />
			<inertia ixx="0.108024" ixy="0" ixz="0" iyy="0.025579" iyz="1.93827e-17" izz="0.112871" />
		</inertial>
	</link>
	<joint name="joint_2" type="revolute">
		<parent link="J1" />
		<child link="J2" />
		<origin rpy="0.000000 0.000000 0.000000" xyz="0.000000 0.000000 0.163500" />
		<axis xyz="-0.000000 1.000000 -0.000000" />
 		<limit lower="-2.0944" upper="2.0944" effort="16.8447" velocity="0.5" />
		<dynamics damping="10" friction="0.1" />
	</joint>
	<transmission name="trans_2">
		<type>transmission_interface/SimpleTransmission</type>
		<joint name="joint_2">
			<hardwareInterface>hardware_interface/EffortJointInterface</hardwareInterface>
		</joint>
		<actuator name="motor_2">
			<hardwareInterface>hardware_interface/EffortJointInterface</hardwareInterface>
			<mechanicalReduction>1</mechanicalReduction>
		</actuator>
	</transmission>
	<link name="J3">
		<visual>
			<origin rpy="0 0 0" xyz="0 0 0" />
			<geometry>
				<mesh filename="package://denso_robot_descriptions/vs060_description/J3.dae" scale="1 1 1" />
			</geometry>
		</visual>
		<collision>
			<origin rpy="0 0 0" xyz="0 0 0" />
			<geometry>
				<mesh filename="package://denso_robot_descriptions/vs060_description/J3.dae" scale="1 1 1" />
			</geometry>
		</collision>
		<inertial>
			<mass value="1" />
			<origin rpy="0.000000 0.000000 0.000000" xyz="0.011544 -0.057408 0.006203" />
			<inertia ixx="0.015999" ixy="0" ixz="0" iyy="0.00638" iyz="2.33191e-18" izz="0.016882" />
		</inertial>
	</link>
	<joint name="joint_3" type="revolute">
		<parent link="J2" />
		<child link="J3" />
		<origin rpy="0.000000 0.000000 0.000000" xyz="0.000000 0.000000 0.305000" />
		<axis xyz="-0.000000 1.000000 -0.000000" />
 		<limit lower="-2.18166" upper="2.70526" effort="20.7089" velocity="0.5" />
		<dynamics damping="10" friction="0.1" />
	</joint>
	<transmission name="trans_3">
		<type>transmission_interface/SimpleTransmission</type>
		<joint name="joint_3">
			<hardwareInterface>hardware_interface/EffortJointInterface</hardwareInterface>
		</joint>
		<actuator name="motor_3">
			<hardwareInterface>hardware_interface/EffortJointInterface</hardwareInterface>
			<mechanicalReduction>1</mechanicalReduction>
		</actuator>
	</transmission>
	<link name="J4">
		<visual>
			<origin rpy="0 0 0" xyz="0 0 0" />
			<geometry>
				<mesh filename="package://denso_robot_descriptions/vs060_description/J4.dae" scale="1 1 1" />
			</geometry>
		</visual>
		<collision>
			<origin rpy="0 0 0" xyz="0 0 0" />
			<geometry>
				<mesh filename="package://denso_robot_descriptions/vs060_description/J4.dae" scale="1 1 1" />
			</geometry>
		</collision>
		<inertial>
			<mass value="1.799" />
			<origin rpy="0.000000 0.000000 0.000000" xyz="0.003998 -0.004975 0.052919" />
			<inertia ixx="0.005106" ixy="0" ixz="0" iyy="0.005266" iyz="-5.87308e-19" izz="0.002621" />
		</inertial>
	</link>
	<joint name="joint_4" type="revolute">
		<parent link="J3" />
		<child link="J4" />
		<origin rpy="0.000000 0.000000 0.000000" xyz="-0.010000 0.000000 0.164500" />
		<axis xyz="-0.000000 -0.000000 1.000000" />
 		<limit lower="-4.71239" upper="4.71239" effort="20.9665" velocity="0.5" />
		<dynamics damping="10" friction="0.1" />
	</joint>
	<transmission name="trans_4">
		<type>transmission_interface/SimpleTransmission</type>
		<joint name="joint_4">
			<hardwareInterface>hardware_interface/EffortJointInterface</hardwareInterface>
		</joint>
		<actuator name="motor_4">
			<hardwareInterface>hardware_interface/EffortJointInterface</hardwareInterface>
			<mechanicalReduction>1</mechanicalReduction>
		</actuator>
	</transmission>
	<link name="J5">
		<visual>
			<origin rpy="0 0 0" xyz="0 0 0" />
			<geometry>
				<mesh filename="package://denso_robot_descriptions/vs060_description/J5.dae" scale="1 1 1" />
			</geometry>
		</visual>
		<collision>
			<origin rpy="0 0 0" xyz="0 0 0" />
			<geometry>
				<mesh filename="package://denso_robot_descriptions/vs060_description/J5.dae" scale="1 1 1" />
			</geometry>
		</collision>
		<inertial>
			<mass value="1.211" />
			<origin rpy="0.000000 0.000000 0.000000" xyz="0.011902 -0.004739 0.010398" />
			<inertia ixx="0.001093" ixy="0" ixz="0" iyy="0.001629" iyz="-3.10862e-21" izz="0.001615" />
		</inertial>
	</link>
	<joint name="joint_5" type="revolute">
		<parent link="J4" />
		<child link="J5" />
		<origin rpy="0.000000 0.000000 0.000000" xyz="0.000000 0.000000 0.135500" />
		<axis xyz="-0.000000 1.000000 -0.000000" />
 		<limit lower="-2.0944" upper="2.0944" effort="23.7229" velocity="0.5" />	
 		<dynamics damping="10" friction="0.1" />
	</joint>
	<transmission name="trans_5">
		<type>transmission_interface/SimpleTransmission</type>
		<joint name="joint_5">
			<hardwareInterface>hardware_interface/EffortJointInterface</hardwareInterface>
		</joint>
		<actuator name="motor_5">
			<hardwareInterface>hardware_interface/EffortJointInterface</hardwareInterface>
			<mechanicalReduction>1</mechanicalReduction>
		</actuator>
	</transmission>
	<link name="J6">
		<visual>
			<origin rpy="0 0 0" xyz="0 0 0" />
			<geometry>
				<mesh filename="package://denso_robot_descriptions/vs060_description/J6.dae" scale="1 1 1" />
			</geometry>
		</visual>
		<collision>
			<origin rpy="0 0 0" xyz="0 0 0" />
			<geometry>
				<mesh filename="package://denso_robot_descriptions/vs060_description/J6.dae" scale="1 1 1" />
			</geometry>
		</collision>
		<inertial>
			<mass value="4.154" />
			<origin rpy="0.000000 0.000000 0.000000" xyz="-0.000401015 0.0770342 0.0962886" />
			<inertia ixx="0.0216473" ixy="-0.000147026" ixz="-0.00011778" iyy="0.0346876" iyz="0.00159321" izz="0.022927" />
		</inertial>
	</link>
	<joint name="joint_6" type="revolute">
		<parent link="J5" />
		<child link="J6" />
		<origin rpy="0.000000 0.000000 0.000000" xyz="0.000000 0.000000 0.070000" />
		<axis xyz="-0.000000 -0.000000 1.000000" />
 	<limit lower="-6.28319" upper="6.28319" effort="33.5103" velocity="0.5" />
 		<dynamics damping="10" friction="0.1" />
	</joint>
	<transmission name="trans_6">
		<type>transmission_interface/SimpleTransmission</type>
		<joint name="joint_6">
			<hardwareInterface>hardware_interface/EffortJointInterface</hardwareInterface>
		</joint>
		<actuator name="motor_6">
			<hardwareInterface>hardware_interface/EffortJointInterface</hardwareInterface>
			<mechanicalReduction>1</mechanicalReduction>
		</actuator>
	</transmission>
	<link name="panda_hand">
		<visual>
			<geometry>
				<mesh filename="package://denso_robot_descriptions/vs060_hand_description/meshes/visual/hand.dae"/>
			</geometry>
		</visual>
		<collision>
			<geometry>
				<mesh filename="package://denso_robot_descriptions/vs060_hand_description/meshes/collision/hand.stl"/>
			</geometry>
		</collision>
      	<inertial>
        	<mass value="0.73" />
        	<origin xyz="0 0.0015244 0.0275912" rpy="0 0 0" />
        	<inertia ixx="0.00278560230025" ixy="0.0" ixz="0.0" iyy="0.000400033405336" iyz="0.0" izz="0.00256378041832" />
		</inertial>
	</link>
	<link name="panda_leftfinger">
		<visual>
			<geometry>
				<mesh filename="package://denso_robot_descriptions/vs060_hand_description/meshes/visual/finger.dae"/>
			</geometry>
		</visual>
		<collision>
			<geometry>
				<mesh filename="package://denso_robot_descriptions/vs060_hand_description/meshes/collision/finger.stl"/>
			</geometry>
		</collision>
      	<inertial>
        	<mass value="0.1" />
        	<origin xyz="0 0.0145644 0.0227941" rpy="0 0 0" />
        	<inertia ixx="3.01220925051e-05" ixy="0.0" ixz="0.0" iyy="2.95873808038e-05" iyz="0.0" izz="6.95125211657e-06" />
		</inertial>
	</link>
	<link name="panda_rightfinger">
		<visual>
			<origin xyz="0 0 0" rpy="0 0 3.1415"/>
			<geometry>
				<mesh filename="package://denso_robot_descriptions/vs060_hand_description/meshes/visual/finger.dae"/>
			</geometry>
		</visual>
		<collision>
			<origin xyz="0 0 0" rpy="0 0 3.1415"/>
			<geometry>
				<mesh filename="package://denso_robot_descriptions/vs060_hand_description/meshes/collision/finger.stl"/>
			</geometry>
		</collision>
      	<inertial>
        	<mass value="0.1" />
        	<origin xyz="0 0.0145644 0.0227941" rpy="0 0 3.1415" />
        	<inertia ixx="3.01220925051e-05" ixy="0.0" ixz="0.0" iyy="2.95873808038e-05" iyz="0.0" izz="6.95125211657e-06" />
			</inertial>
	</link>
	<joint name="panda_finger_joint1" type="prismatic">
		<parent link="panda_hand"/>
		<child link="panda_leftfinger"/>
		<origin xyz="0 0 0.0584" rpy="0 0 0"/>
		<axis xyz="0 1 0"/>
		<limit effort="20" lower="0.0" upper="0.04" velocity="0.2"/>
	</joint>
	<transmission name="trans_hand1">
		<type>transmission_interface/SimpleTransmission</type>
		<joint name="panda_finger_joint1">
			<hardwareInterface>hardware_interface/EffortJointInterface</hardwareInterface>
		</joint>
		<actuator name="motor_hand_1">
			<hardwareInterface>hardware_interface/EffortJointInterface</hardwareInterface>
			<mechanicalReduction>1</mechanicalReduction>
		</actuator>
	</transmission>
	<joint name="panda_finger_joint2" type="prismatic">
		<parent link="panda_hand"/>
		<child link="panda_rightfinger"/>
		<origin xyz="0 0 0.0584" rpy="0 0 0"/>
		<axis xyz="0 -1 0"/>
		<limit effort="20" lower="0.0" upper="0.04" velocity="0.2"/>
	</joint>
	<transmission name="trans_hand2">
		<type>transmission_interface/SimpleTransmission</type>
		<joint name="panda_finger_joint2">
			<hardwareInterface>hardware_interface/EffortJointInterface</hardwareInterface>
		</joint>
		<actuator name="motor_hand_2">
			<hardwareInterface>hardware_interface/EffortJointInterface</hardwareInterface>
			<mechanicalReduction>1</mechanicalReduction>
		</actuator>
	</transmission>
	<joint name="panda_hand_joint" type="fixed">
			<parent link="J6"/>
			<child link="panda_hand"/>
			<origin xyz="0 0 0.002" rpy="0 0 0.0"/>
	</joint>

	<gazebo reference="J1">
		<gravity>0</gravity>
		<!-- <kp>1000000.0</kp>
		<kd>1.0</kd>
		<mu1>0.8</mu1>
		<mu2>0.8</mu2>
		<maxVel>0.0</maxVel>
		<minDepth>0.001</minDepth> -->
	</gazebo>

	<gazebo reference="J2">
		<gravity>0</gravity>
		<!-- <kp>1000000.0</kp>
		<kd>1.0</kd>
		<mu1>0.8</mu1>
		<mu2>0.8</mu2>
		<maxVel>0.0</maxVel>
		<minDepth>0.001</minDepth> -->
	</gazebo>

	<gazebo reference="J3">
		<gravity>0</gravity>
		<!-- <kp>1000000.0</kp>
		<kd>1.0</kd>
		<mu1>0.8</mu1>
		<mu2>0.8</mu2>
		<maxVel>0.0</maxVel>
		<minDepth>0.001</minDepth> -->
	</gazebo>

	<gazebo reference="J4">
		<gravity>0</gravity>
		<!-- <kp>1000000.0</kp>
		<kd>1.0</kd>
		<mu1>0.8</mu1>
		<mu2>0.8</mu2>
		<maxVel>0.0</maxVel>
		<minDepth>0.001</minDepth> -->
	</gazebo>

	<gazebo reference="J5">
		<gravity>0</gravity>
		<!-- <kp>1000000.0</kp>
		<kd>1.0</kd>
		<mu1>0.8</mu1>
		<mu2>0.8</mu2>
		<maxVel>0.0</maxVel>
		<minDepth>0.001</minDepth> -->
	</gazebo>

	<gazebo reference="J6">
		<gravity>0</gravity>
		<!-- <kp>1000000.0</kp>
		<kd>1.0</kd>
		<mu1>0.8</mu1>
		<mu2>0.8</mu2>
		<maxVel>0.0</maxVel>
		<minDepth>0.001</minDepth> -->
	</gazebo>

	<gazebo reference="panda_hand">
		<gravity>0</gravity>
		<!-- <kp>1000000.0</kp>
		<kd>1.0</kd>
		<mu1>0.8</mu1>
		<mu2>0.8</mu2>
		<maxVel>0.0</maxVel>
		<minDepth>0.001</minDepth> -->
	</gazebo>

	<gazebo reference="panda_rightfinger">
		<gravity>0</gravity>
		<!-- <kp>1000000.0</kp>
		<kd>1.0</kd>
		<mu1>0.8</mu1>
		<mu2>0.8</mu2>
		<maxVel>0.0</maxVel>
		<minDepth>0.001</minDepth> -->
	</gazebo>

	<gazebo reference="panda_leftfinger">
		<gravity>0</gravity>
		<!-- <kp>1000000.0</kp>
		<kd>1.0</kd>
		<mu1>0.8</mu1>
		<mu2>0.8</mu2>
		<maxVel>0.0</maxVel>
		<minDepth>0.001</minDepth> -->
	</gazebo>

</robot>